Workbook
Name AUHAgeBr: 'Final premium per member'!$U$5:$V$17
Name DXBAgeBr: 'Final premium per member'!$T$5:$V$17

Sheet Approved Quote
A1: Policyholder: | C1: MGH LOGISTICS L.L.C
A2: Start Date: | C2: 46105
A3: Broker Name: | C3: Savington International Insurance Brokers LLC
A6: PREMIUM OVERVIEW
A8: TOTAL PREMIUM | F8: =I35+I59+I83+I107& " members" -> 17 members | I8: =SUM(I34,I58,I82,I106) -> 165194
A9: BASMAH FEE (AED 37 / member) | F9: =I35+I59+I83+I107& " members" -> 17 members | I9: =(I35+I59+I83+I107)*37 -> 629
A10: SLASH DATA FEE (AED 25 / member) | F10: 0 Rest of UAE members | I10: 0
A11: ADDITIONAL LOADING | F11: Additional loading for pre-existing conditions
A12: VALUE ADDED TAX (VAT) | F12: 0.05 | I12: =SUM(I8:J11)*5% -> 8291.15
I13: =SUM(I8:J12) -> 174114.15
A16: Category A
B18: PRINCIPAL | G18: DEPENDENTS | P18: Cat A
A19: Age Range | B19: Premium | C19: Male | D19: Premium | E19: Female | G19: Premium | H19: Male | I19: Premium | J19: Female | P19: Principal | Q19: Dependents
A20: 0 - 10 | B20: 4600 | D20: 3600 | G20: 6499 | I20: 5234 | J20: 5 | O20: 0-10 | P20: =B20*C20+D20*E20 -> 0 | Q20: =G20*H20+I20*J20 -> 26170 | R20: 0
A21: 11 - 17 | B21: 3157 | D21: 3217 | G21: 4674 | I21: 4750 | J21: 1 | O21: 11-17 | P21: =B21*C21+D21*E21 -> 0 | Q21: =G21*H21+I21*J21 -> 4750
A22: 18 - 25 | B22: 5253 | C22: 1 | D22: 5997 | G22: 5253 | I22: 5997 | O22: 18-25 | P22: =B22*C22+D22*E22 -> 5253 | Q22: =G22*H22+I22*J22 -> 0
A23: 26 - 30 | B23: 5833 | C23: 1 | D23: 7304 | E23: 1 | G23: 5833 | I23: 7304 | J23: 2 | O23: 26-30 | P23: =B23*C23+D23*E23 -> 13137 | Q23: =G23*H23+I23*J23 -> 14608
A24: 31 - 35 | B24: 6915 | C24: 1 | D24: 8606 | G24: 6915 | I24: 8606 | O24: 31-35 | P24: =B24*C24+D24*E24 -> 6915 | Q24: =G24*H24+I24*J24 -> 0
A25: 36 - 40 | B25: 8397 | C25: 1 | D25: 10589 | G25: 8397 | I25: 10589 | M25: 2599 | O25: 36-40 | P25: =B25*C25+D25*E25 -> 8397 | Q25: =G25*H25+I25*J25 -> 0 | S25: 25596 | T25: 0 | U25: 25596
A26: 41 - 45 | B26: 8785 | C26: 1 | D26: 12068 | G26: 8795 | I26: 12068 | J26: 1 | M26: 2716 | O26: 41-45 | P26: =B26*C26+D26*E26 -> 8785 | Q26: =G26*H26+I26*J26 -> 12068
A27: 46 - 50 | B27: 11304 | D27: 14951 | G27: 11304 | I27: 14951 | M27: -117 | O27: 46-50 | P27: =B27*C27+D27*E27 -> 0 | Q27: =G27*H27+I27*J27 -> 0
A28: 51 - 55 | B28: 14946 | D28: 19507 | G28: 14946 | I28: 19507 | J28: 1 | O28: 51-55 | P28: =B28*C28+D28*E28 -> 0 | Q28: =G28*H28+I28*J28 -> 19507
A29: 56 - 59 | B29: 20128 | D29: 23729 | G29: 20128 | I29: 23729 | O29: 56-59 | P29: =B29*C29+D29*E29 -> 0 | Q29: =G29*H29+I29*J29 -> 0
A30: 60 - 64 | B30: 24628 | C30: 1 | D30: 28071 | G30: 24628 | I30: 28071 | M30: -4.5017314 | O30: 60-64 | P30: =B30*C30+D30*E30 -> 24628 | Q30: =G30*H30+I30*J30 -> 0
A31: 65 - 99 | B31: 43786 | D31: 49985 | G31: 43786 | I31: 49985 | O31: 65-99 | P31: =B31*C31+D31*E31 -> 0 | Q31: =G31*H31+I31*J31 -> 0
A32: Subtotals | C32: =SUM(C20:C31) -> 6 | E32: =SUM(E20:E31) -> 1 | H32: =SUM(H20:H31) -> 0 | J32: =SUM(J20:J31) -> 10 | O32: Subtotals | P32: =SUM(P20:P31) -> 67115 | Q32: =SUM(Q20:Q31) -> 77103
A33: For members 65 years old & above, the premium quoted is INDICATIVE only and subject to completion of the Medical Application Form (MAF), Medical Examination Report (MER). Further blood tests, and ECG are required for 70+ years old members.
A34: Maternity Premium (18-45) | C34: =C36*C35 -> 20976 | G34: Category Premium | I34: =P32+C34+Q32 -> 165194
A35: Census | C35: 4 | G35: Category Members | I35: =SUM(C20:C31,E20:E31,H20:H31,J20:J31) -> 17
A36: Average | C36: 5244 | G36: Average | I36: =I34/I35 -> 9717.2941
A40: Category B
B42: PRINCIPAL | G42: DEPENDENTS | P42: Cat B
A43: Age Range | B43: Premium | C43: Male | D43: Premium | E43: Female | G43: Premium | H43: Male | I43: Premium | J43: Female | P43: Principal | Q43: Dependents
O44: 0-10 | P44: =B44*C44+D44*E44 -> 0 | Q44: =G44*H44+I44*J44 -> 0
O45: 11-17 | P45: =B45*C45+D45*E45 -> 0 | Q45: =G45*H45+I45*J45 -> 0
O46: 18-25 | P46: =B46*C46+D46*E46 -> 0 | Q46: =G46*H46+I46*J46 -> 0
O47: 26-30 | P47: =B47*C47+D47*E47 -> 0 | Q47: =G47*H47+I47*J47 -> 0
O48: 31-35 | P48: =B48*C48+D48*E48 -> 0 | Q48: =G48*H48+I48*J48 -> 0
O49: 36-40 | P49: =B49*C49+D49*E49 -> 0 | Q49: =G49*H49+I49*J49 -> 0
O50: 41-45 | P50: =B50*C50+D50*E50 -> 0 | Q50: =G50*H50+I50*J50 -> 0
...

Sheet Confirmation Info Sheet
A1: Company Name | B1: ='Approved Quote'!C1 -> MGH LOGISTICS L.L.C | E1: Categories | F1: 1 | G1: Subgroups | H1: 1
A2: Start Date | B2: {='Approved Quote'!C2:D2} -> 46105 | C2: 0 | E2: Confirmed Premium | F2: ='Approved Quote'!I8 -> 165194 | G2: Members | H2: ='Approved Quote'!I35+'Approved Quote'!I59+'Approved Quote'!I83+'Approved Quote'!I107 -> 17
A3: Broker/Contact Person | B3: ='Approved Quote'!C3 -> Savington International Insurance Brokers LLC | E3: Confirmed Quotation No.
A4: Commission | B4: 0.1 | E4: Final Premium (if not same as confirmed census) | F4: ='Premium Table'!U14 -> Same as confirmed quote | G4: Members | H4: ='Premium Table'!U15
A5: Current insurer | E5: Over 64 | F5: =COUNTIF('Final premium per member'!L6:L506,">64") -> 0 | G5: =F5/H4 -> #VALUE!
A6: Emirate | B6: Dubai | E6: LSB (Low-salary band) members | F6: 0 | G6: No
A7: Underwriter | B7: Mabel | E7: Dubai members | F7: 14
A8: Type | B8: New Business | E8: Abu Dhabi members | F8: 0
A9: Inception premium payment | B9: Annual | E9: Northern Emirates members | F9: 0
A10: Endorsement Frequency | B10: Monthly | E10: Outside UAE members | F10: 0
B12: Documents required | C12: Status | D12: Date Received | E12: Comments
B13: Census List
B14: Medical Application Form
B15: Declaration Form | E15: Clean declaration
B16: Photographs (.jpg format, Filename - member name)
B17: Continuity Certificate from Previous Insurer
B18: eKYC Form
B19: Bank Account details with IBAN of the Group/ Sub-groups
B20: Signed and Stamped TOB
B21: Ministry of Labour List
B22: Trade License copy
B23: Vat Registration Number and Certificates
B24: Establishment ID copy
B25: Name/s and Address/es to be mentioned in the Tax Invoice
B26: Salary Declaration Form (for LSB members)
B27: Other supporting document
B30: Internal documents | C30: Status | D30: Date Received | E30: Comments
B31: Premium summary | E31: Waiting for confirmation from RGA and manual AUH rates.
B32: TOB with exclusions
B33: RGA assessment | C33: N/A
B36: Confirmation steps | C36: Status | D36: Date Sent | E36: Documents to attach | F36: Comments
B37: Documents sent to NAS | E37: TOB with exclusions, Premium Summary, Tool
B38: Documents sent to QIC
B39: Documents sent to RGA | E39: Tool, Signed Quote, Census | F39: Tool, Signed Quote, Census
B40: Policy activation
B41: E-cards issuance
B42: Policy documents issuance
A44: Subject: | B44: ="QIC-HEALTHX- UAE - QS - SME - "&B1&" - UW Review" -> QIC-HEALTHX- UAE - QS - SME - MGH LOGISTICS L.L.C - UW Review
A45: Hi Amrit/Shubham,
A47: Please find attached confirmed quote, GDF (clean), census, and RGA tool for your kind checking and confirmation:
...

Sheet Email Helper
A2: Email documents to QIC
A4: Subject: | B4: ="Confirmation - "&'Confirmation Info Sheet'!B1&" effective on "&TEXT('Confirmation Info Sheet'!B2,"dd mmm yyy") -> Confirmation - MGH LOGISTICS L.L.C effective on 24 Mar 2026
A7: Dear Minhas,
A9: ="Healthx is pleased to share the below onboarding documents for "&'Confirmation Info Sheet'!B1&":" -> Healthx is pleased to share the below onboarding documents for MGH LOGISTICS L.L.C:
A11: =IF('Confirmation Info Sheet'!C13="Completed","- "&'Confirmation Info Sheet'!B13,"")
A12: =IF('Confirmation Info Sheet'!C14="Completed","- "&'Confirmation Info Sheet'!B14,"")
A13: =IF('Confirmation Info Sheet'!C15="Completed","- "&'Confirmation Info Sheet'!B15&" ("&'Confirmation Info Sheet'!E15&")","")
A14: =IF('Confirmation Info Sheet'!C16="Completed","- "&'Confirmation Info Sheet'!B16,"")
A15: =IF('Confirmation Info Sheet'!C17="Completed","- "&'Confirmation Info Sheet'!B17,"")
A16: - eKYC form - QIC to send the link to the client?
A17: =IF('Confirmation Info Sheet'!C19="Completed","- "&'Confirmation Info Sheet'!B19,"")
A18: =IF('Confirmation Info Sheet'!C20="Completed","- "&'Confirmation Info Sheet'!B20,"")
A19: =IF('Confirmation Info Sheet'!C21="Completed","- "&'Confirmation Info Sheet'!B21,"")
A20: =IF('Confirmation Info Sheet'!C22="Completed","- "&'Confirmation Info Sheet'!B22,"")
A21: =IF('Confirmation Info Sheet'!C23="Completed","- "&'Confirmation Info Sheet'!B23,"")
A22: =IF('Confirmation Info Sheet'!C24="Completed","- "&'Confirmation Info Sheet'!B24,"")
A23: =IF('Confirmation Info Sheet'!C25="Completed","- "&'Confirmation Info Sheet'!B25,"")
A24: =IF('Confirmation Info Sheet'!C26="Completed","- "&'Confirmation Info Sheet'!B26,"")
A25: =IF('Confirmation Info Sheet'!C27="Completed","- "&'Confirmation Info Sheet'!E27,"")
A26: - TOBs with exclusions
A27: - RGA pricing tool
A29: Policy Name | B29: ='Confirmation Info Sheet'!B1 -> MGH LOGISTICS L.L.C
A30: Policy start date | B30: ='Confirmation Info Sheet'!B2 -> 46105
A31: Broker Name | B31: ='Confirmation Info Sheet'!B3 -> Savington International Insurance Brokers LLC
A32: Payment Terms | B32: ='Confirmation Info Sheet'!B9 -> Annual
A33: Confirmed quote | B33: ='Premium Table'!U11 -> 165194
A34: Premium as per final census | B34: ='Premium Table'!U14 -> Same as confirmed quote
A36: ='Premium Table'!N11 -> Broker | B36: ='Premium Table'!O11 -> 0.1
A37: ='Premium Table'!N12 -> NAS (TPA) | B37: ='Premium Table'!O12 -> 0.05
A38: ='Premium Table'!N13 -> QIC (Insurer) | B38: ='Premium Table'!O13+'Premium Table'!O15 -> 0.005
A39: ='Premium Table'!N14 -> HealthX (Admin) | B39: ='Premium Table'!O14 -> 0.05
A41: Please advise if you require anything further.
A43: Email documents to NAS
A45: To:
A46: Healthxendorsments@nas.ae
A47: Cheri.Jijo@nas.ae
A49: Cc: QIC team
A51: Subject: | B51: ="Confirmation - "&'Confirmation Info Sheet'!B1&" effective on "&TEXT('Confirmation Info Sheet'!B2,"dd mmm yyy") -> Confirmation - MGH LOGISTICS L.L.C effective on 24 Mar 2026
A54: Dear NAS team,
A56: Healthx is pleased to share the onboarding documents for policy activation.
...

Sheet Premium Table
A3: Product | B3: QIC Dubai Branch - Healthx | N3: FLAT FIXED FEES
A4: Policy Holder | B4: ='Confirmation Info Sheet'!B1 -> MGH LOGISTICS L.L.C | N4: DHA Basmah Fee | O4: 19 | P4: Paid by client
N5: DHA HCV Fee | O5: 18 | P5: Paid by client
A6: Policy Start Date | B6: ='Confirmation Info Sheet'!B2 -> 46105 | N6: TruDoc Fee | O6: 12 | P6: Paid by Healthx
A7: Policy End Date | B7: =DATE(YEAR(B6)+1,MONTH(B6),DAY(B6))-1 -> 46469 | N7: Slash Data Fee | O7: 0
A8: Policy Type | B8: ='Confirmation Info Sheet'!B8 -> New Business
O9: FEES IN %
A10: Inception premium payment | B10: ='Confirmation Info Sheet'!B9 -> Annual | O10: HSB | Q10: LSB
A11: Endorsement Frequency | B11: ='Confirmation Info Sheet'!B10 -> Monthly | N11: Broker | O11: ='Confirmation Info Sheet'!B4 -> 0.1 | Q11: 0.05 | T11: Confirmed Quote | U11: ='Approved Quote'!I8 -> 165194 | W11: Per Capita | X11: =U11/U12 -> 9717.2941
N12: NAS (TPA) | O12: 0.05 | Q12: 0.05 | T12: Members | U12: ='Confirmation Info Sheet'!H2 -> 17
A13: Underwriter | B13: Mabel Orleans | G13: 46111 | N13: QIC (Insurer) | O13: 0 | Q13: =O13+((O11-Q11)/2) -> 0.025
A14: Validated by | N14: HealthX (Admin) | O14: 0.05 | Q14: =O14+((O11-Q11)/2) -> 0.075 | T14: Final Premium | U14: =IF(U11='Final premium per member'!R2,"Same as confirmed quote",'Final premium per member'!R2) -> Same as confirmed quote | W14: Per Capita | X14: =IF(U11='Final premium per member'!R2,"",U14/U15)
N15: Insurance Levy | O15: 0.005 | Q15: 0.005 | T15: Members | U15: =IF(U11='Final premium per member'!R2,"",'Final premium per member'!R3)
N16: TOTAL FEES | O16: =SUM(O11:O15) -> 0.205 | Q16: =SUM(Q11:Q15) -> 0.205
T17: Premium Variance | U17: =IF(ISERROR(U14/U11-1),"",U14/U11-1)
A19: Category | B19: Age Band | C19: =N4 -> DHA Basmah Fee | D19: =N5 -> DHA HCV Fee | E19: =N6 -> TruDoc Fee | F19: =N7 -> Slash Data Fee | G19: GROSS PREMIUM (MALE) | H19: GROSS PREMIUM (FEMALE) | I19: =N11 -> Broker | J19: =N12 -> NAS (TPA) | K19: =N13 -> QIC (Insurer) | L19: =N14 -> HealthX (Admin) | M19: =N15 -> Insurance Levy | N19: NET PREMIUM (MALE) | O19: NET PREMIUM (FEMALE) | T19: Members Variance | U19: =IF(ISERROR(U15/U12-1),"",U15/U12-1) | V19: If more than -10%, either revised quote or seek approval from RGA
A20: Category A | Q20: Net Rates Check | T20: Per Capita Variance | U20: =IF(ISERROR(X14/X11-1),"",X14/X11-1)
A21: Cat A (EMP) | B21: ='Approved Quote'!A21 -> 11 - 17 | C21: 19 | D21: 18 | E21: 12 | G21: ='Final premium per member'!W7 -> 3157 | H21: ='Final premium per member'!X7 -> 3217 | I21: =$O$11 -> 0.1 | J21: =$O$12 -> 0.05 | K21: =$O$13 -> 0 | L21: =$O$14 -> 0.05 | M21: =$O$15 -> 0.005 | N21: =IF(G21="","",G21*(1-$O$16)) -> 2509.815 | O21: =IF(H21="","",H21*(1-$O$16)) -> 2557.515 | Q21: =N21-#REF! -> #REF! | R21: =O21-#REF! -> #REF!
A22: Cat A (EMP) | B22: ='Approved Quote'!A22 -> 18 - 25 | C22: 19 | D22: 18 | E22: 12 | G22: ='Final premium per member'!W8 -> 5253 | H22: ='Final premium per member'!X8 -> 5997 | I22: =$O$11 -> 0.1 | J22: =$O$12 -> 0.05 | K22: =$O$13 -> 0 | L22: =$O$14 -> 0.05 | M22: =$O$15 -> 0.005 | N22: =IF(G22="","",G22*(1-$O$16)) -> 4176.135 | O22: =IF(H22="","",H22*(1-$O$16)) -> 4767.615 | Q22: =N22-#REF! -> #REF! | R22: =O22-#REF! -> #REF! | T22: Additional Loading
A23: Cat A (EMP) | B23: ='Approved Quote'!A23 -> 26 - 30 | C23: 19 | D23: 18 | E23: 12 | G23: ='Final premium per member'!W9 -> 5833 | H23: ='Final premium per member'!X9 -> 7304 | I23: =$O$11 -> 0.1 | J23: =$O$12 -> 0.05 | K23: =$O$13 -> 0 | L23: =$O$14 -> 0.05 | M23: =$O$15 -> 0.005 | N23: =IF(G23="","",G23*(1-$O$16)) -> 4637.235 | O23: =IF(H23="","",H23*(1-$O$16)) -> 5806.68 | Q23: =N23-#REF! -> #REF! | R23: =O23-#REF! -> #REF!
A24: Cat A (EMP) | B24: ='Approved Quote'!A24 -> 31 - 35 | C24: 19 | D24: 18 | E24: 12 | G24: ='Final premium per member'!W10 -> 6915 | H24: ='Final premium per member'!X10 -> 8606 | I24: =$O$11 -> 0.1 | J24: =$O$12 -> 0.05 | K24: =$O$13 -> 0 | L24: =$O$14 -> 0.05 | M24: =$O$15 -> 0.005 | N24: =IF(G24="","",G24*(1-$O$16)) -> 5497.425 | O24: =IF(H24="","",H24*(1-$O$16)) -> 6841.77 | Q24: =N24-#REF! -> #REF! | R24: =O24-#REF! -> #REF! | T24: Net Loading | U24: =U25*(1-O16) -> 0
A25: Cat A (EMP) | B25: ='Approved Quote'!A25 -> 36 - 40 | C25: 19 | D25: 18 | E25: 12 | G25: ='Final premium per member'!W11 -> 8397 | H25: ='Final premium per member'!X11 -> 10589 | I25: =$O$11 -> 0.1 | J25: =$O$12 -> 0.05 | K25: =$O$13 -> 0 | L25: =$O$14 -> 0.05 | M25: =$O$15 -> 0.005 | N25: =IF(G25="","",G25*(1-$O$16)) -> 6675.615 | O25: =IF(H25="","",H25*(1-$O$16)) -> 8418.255 | Q25: =N25-#REF! -> #REF! | R25: =O25-#REF! -> #REF! | T25: Gross Loading | U25: ='Approved Quote'!I11 -> 0
A26: Cat A (EMP) | B26: ='Approved Quote'!A26 -> 41 - 45 | C26: 19 | D26: 18 | E26: 12 | G26: ='Final premium per member'!W12 -> 8785 | H26: ='Final premium per member'!X12 -> 12068 | I26: =$O$11 -> 0.1 | J26: =$O$12 -> 0.05 | K26: =$O$13 -> 0 | L26: =$O$14 -> 0.05 | M26: =$O$15 -> 0.005 | N26: =IF(G26="","",G26*(1-$O$16)) -> 6984.075 | O26: =IF(H26="","",H26*(1-$O$16)) -> 9594.06 | Q26: =N26-#REF! -> #REF! | R26: =O26-#REF! -> #REF!
A27: Cat A (EMP) | B27: ='Approved Quote'!A27 -> 46 - 50 | C27: 19 | D27: 18 | E27: 12 | G27: ='Final premium per member'!W13 -> 11304 | H27: ='Final premium per member'!X13 -> 14951 | I27: =$O$11 -> 0.1 | J27: =$O$12 -> 0.05 | K27: =$O$13 -> 0 | L27: =$O$14 -> 0.05 | M27: =$O$15 -> 0.005 | N27: =IF(G27="","",G27*(1-$O$16)) -> 8986.68 | O27: =IF(H27="","",H27*(1-$O$16)) -> 11886.045 | Q27: =N27-#REF! -> #REF! | R27: =O27-#REF! -> #REF!
A28: Cat A (EMP) | B28: ='Approved Quote'!A28 -> 51 - 55 | C28: 19 | D28: 18 | E28: 12 | G28: ='Final premium per member'!W14 -> 14946 | H28: ='Final premium per member'!X14 -> 19507 | I28: =$O$11 -> 0.1 | J28: =$O$12 -> 0.05 | K28: =$O$13 -> 0 | L28: =$O$14 -> 0.05 | M28: =$O$15 -> 0.005 | N28: =IF(G28="","",G28*(1-$O$16)) -> 11882.07 | O28: =IF(H28="","",H28*(1-$O$16)) -> 15508.065 | Q28: =N28-#REF! -> #REF! | R28: =O28-#REF! -> #REF! | T28: Member | U28: DOB | V28: Gender | W28: Category | X28: Relation | Y28: Net Loading | Z28: Gross Loading | AA28: Declaration | AB28: Comments
A29: Cat A (EMP) | B29: ='Approved Quote'!A29 -> 56 - 59 | C29: 19 | D29: 18 | E29: 12 | G29: ='Final premium per member'!W15 -> 20128 | H29: ='Final premium per member'!X15 -> 23729 | I29: =$O$11 -> 0.1 | J29: =$O$12 -> 0.05 | K29: =$O$13 -> 0 | L29: =$O$14 -> 0.05 | M29: =$O$15 -> 0.005 | N29: =IF(G29="","",G29*(1-$O$16)) -> 16001.76 | O29: =IF(H29="","",H29*(1-$O$16)) -> 18864.555 | Q29: =N29-#REF! -> #REF! | R29: =O29-#REF! -> #REF!
A30: Cat A (EMP) | B30: ='Approved Quote'!A30 -> 60 - 64 | C30: 19 | D30: 18 | E30: 12 | G30: ='Final premium per member'!W16 -> 24628 | H30: ='Final premium per member'!X16 -> 28071 | I30: =$O$11 -> 0.1 | J30: =$O$12 -> 0.05 | K30: =$O$13 -> 0 | L30: =$O$14 -> 0.05 | M30: =$O$15 -> 0.005 | N30: =IF(G30="","",G30*(1-$O$16)) -> 19579.26 | O30: =IF(H30="","",H30*(1-$O$16)) -> 22316.445 | Q30: =N30-#REF! -> #REF! | R30: =O30-#REF! -> #REF!
A31: Cat A (EMP) | B31: ='Approved Quote'!A31 -> 65 - 99 | G31: ='Final premium per member'!W17 -> 43786 | H31: ='Final premium per member'!X17 -> 49985 | I31: =$O$11 -> 0.1 | J31: =$O$12 -> 0.05 | K31: =$O$13 -> 0 | L31: =$O$14 -> 0.05 | M31: =$O$15 -> 0.005 | N31: =IF(G31="","",G31*(1-$O$16)) -> 34809.87 | O31: =IF(H31="","",H31*(1-$O$16)) -> 39738.075 | Q31: =N32-#REF! -> #REF! | R31: =O32-#REF! -> #REF!
A32: Cat A (DEP) | B32: ='Approved Quote'!A20 -> 0 - 10 | C32: 19 | D32: 18 | E32: 12 | G32: ='Final premium per member'!Y6 -> 6499 | H32: ='Final premium per member'!Z6 -> 5234 | I32: =$O$11 -> 0.1 | J32: =$O$12 -> 0.05 | K32: =$O$13 -> 0 | L32: =$O$14 -> 0.05 | M32: =$O$15 -> 0.005 | N32: =IF(G32="","",G32*(1-$O$16)) -> 5166.705 | O32: =IF(H32="","",H32*(1-$O$16)) -> 4161.03 | Q32: =N33-#REF! -> #REF! | R32: =O33-#REF! -> #REF!
A33: Cat A (DEP) | B33: ='Approved Quote'!A21 -> 11 - 17 | C33: 19 | D33: 18 | E33: 12 | G33: ='Final premium per member'!Y7 -> 4674 | H33: ='Final premium per member'!Z7 -> 4750 | I33: =$O$11 -> 0.1 | J33: =$O$12 -> 0.05 | K33: =$O$13 -> 0 | L33: =$O$14 -> 0.05 | M33: =$O$15 -> 0.005 | N33: =IF(G33="","",G33*(1-$O$16)) -> 3715.83 | O33: =IF(H33="","",H33*(1-$O$16)) -> 3776.25 | Q33: =N34-#REF! -> #REF! | R33: =O34-#REF! -> #REF! | Y33: =SUM(Y29:Y32) -> 0 | Z33: =SUM(Z29:Z32) -> 0
A34: Cat A (DEP) | B34: ='Approved Quote'!A22 -> 18 - 25 | C34: 19 | D34: 18 | E34: 12 | G34: ='Final premium per member'!Y8 -> 5253 | H34: ='Final premium per member'!Z8 -> 5997 | I34: =$O$11 -> 0.1 | J34: =$O$12 -> 0.05 | K34: =$O$13 -> 0 | L34: =$O$14 -> 0.05 | M34: =$O$15 -> 0.005 | N34: =IF(G34="","",G34*(1-$O$16)) -> 4176.135 | O34: =IF(H34="","",H34*(1-$O$16)) -> 4767.615 | Q34: =N35-#REF! -> #REF! | R34: =O35-#REF! -> #REF!
A35: Cat A (DEP) | B35: ='Approved Quote'!A23 -> 26 - 30 | C35: 19 | D35: 18 | E35: 12 | G35: ='Final premium per member'!Y9 -> 5833 | H35: ='Final premium per member'!Z9 -> 7304 | I35: =$O$11 -> 0.1 | J35: =$O$12 -> 0.05 | K35: =$O$13 -> 0 | L35: =$O$14 -> 0.05 | M35: =$O$15 -> 0.005 | N35: =IF(G35="","",G35*(1-$O$16)) -> 4637.235 | O35: =IF(H35="","",H35*(1-$O$16)) -> 5806.68 | Q35: =N36-#REF! -> #REF! | R35: =O36-#REF! -> #REF!
A36: Cat A (DEP) | B36: ='Approved Quote'!A24 -> 31 - 35 | C36: 19 | D36: 18 | E36: 12 | G36: ='Final premium per member'!Y10 -> 6915 | H36: ='Final premium per member'!Z10 -> 8606 | I36: =$O$11 -> 0.1 | J36: =$O$12 -> 0.05 | K36: =$O$13 -> 0 | L36: =$O$14 -> 0.05 | M36: =$O$15 -> 0.005 | N36: =IF(G36="","",G36*(1-$O$16)) -> 5497.425 | O36: =IF(H36="","",H36*(1-$O$16)) -> 6841.77 | Q36: =N37-#REF! -> #REF! | R36: =O37-#REF! -> #REF!
A37: Cat A (DEP) | B37: ='Approved Quote'!A25 -> 36 - 40 | C37: 19 | D37: 18 | E37: 12 | G37: ='Final premium per member'!Y11 -> 8397 | H37: ='Final premium per member'!Z11 -> 10589 | I37: =$O$11 -> 0.1 | J37: =$O$12 -> 0.05 | K37: =$O$13 -> 0 | L37: =$O$14 -> 0.05 | M37: =$O$15 -> 0.005 | N37: =IF(G37="","",G37*(1-$O$16)) -> 6675.615 | O37: =IF(H37="","",H37*(1-$O$16)) -> 8418.255 | Q37: =N38-#REF! -> #REF! | R37: =O38-#REF! -> #REF!
A38: Cat A (DEP) | B38: ='Approved Quote'!A26 -> 41 - 45 | C38: 19 | D38: 18 | E38: 12 | G38: ='Final premium per member'!Y12 -> 8795 | H38: ='Final premium per member'!Z12 -> 12068 | I38: =$O$11 -> 0.1 | J38: =$O$12 -> 0.05 | K38: =$O$13 -> 0 | L38: =$O$14 -> 0.05 | M38: =$O$15 -> 0.005 | N38: =IF(G38="","",G38*(1-$O$16)) -> 6992.025 | O38: =IF(H38="","",H38*(1-$O$16)) -> 9594.06 | Q38: =N39-#REF! -> #REF! | R38: =O39-#REF! -> #REF!
A39: Cat A (DEP) | B39: ='Approved Quote'!A27 -> 46 - 50 | C39: 19 | D39: 18 | E39: 12 | G39: ='Final premium per member'!Y13 -> 11304 | H39: ='Final premium per member'!Z13 -> 14951 | I39: =$O$11 -> 0.1 | J39: =$O$12 -> 0.05 | K39: =$O$13 -> 0 | L39: =$O$14 -> 0.05 | M39: =$O$15 -> 0.005 | N39: =IF(G39="","",G39*(1-$O$16)) -> 8986.68 | O39: =IF(H39="","",H39*(1-$O$16)) -> 11886.045 | Q39: =N40-#REF! -> #REF! | R39: =O40-#REF! -> #REF!
A40: Cat A (DEP) | B40: ='Approved Quote'!A28 -> 51 - 55 | C40: 19 | D40: 18 | E40: 12 | G40: ='Final premium per member'!Y14 -> 14946 | H40: ='Final premium per member'!Z14 -> 19507 | I40: =$O$11 -> 0.1 | J40: =$O$12 -> 0.05 | K40: =$O$13 -> 0 | L40: =$O$14 -> 0.05 | M40: =$O$15 -> 0.005 | N40: =IF(G40="","",G40*(1-$O$16)) -> 11882.07 | O40: =IF(H40="","",H40*(1-$O$16)) -> 15508.065 | Q40: =N41-#REF! -> #REF! | R40: =O41-#REF! -> #REF!
A41: Cat A (DEP) | B41: ='Approved Quote'!A29 -> 56 - 59 | C41: 19 | D41: 18 | E41: 12 | G41: ='Final premium per member'!Y15 -> 20128 | H41: ='Final premium per member'!Z15 -> 23729 | I41: =$O$11 -> 0.1 | J41: =$O$12 -> 0.05 | K41: =$O$13 -> 0 | L41: =$O$14 -> 0.05 | M41: =$O$15 -> 0.005 | N41: =IF(G41="","",G41*(1-$O$16)) -> 16001.76 | O41: =IF(H41="","",H41*(1-$O$16)) -> 18864.555 | Q41: =N42-#REF! -> #REF! | R41: =O42-#REF! -> #REF!
A42: Cat A (DEP) | B42: ='Approved Quote'!A30 -> 60 - 64 | C42: 19 | D42: 18 | E42: 12 | G42: ='Final premium per member'!Y16 -> 24628 | H42: ='Final premium per member'!Z16 -> 28071 | I42: =$O$11 -> 0.1 | J42: =$O$12 -> 0.05 | K42: =$O$13 -> 0 | L42: =$O$14 -> 0.05 | M42: =$O$15 -> 0.005 | N42: =IF(G42="","",G42*(1-$O$16)) -> 19579.26 | O42: =IF(H42="","",H42*(1-$O$16)) -> 22316.445
A43: Cat A (DEP) | B43: ='Approved Quote'!A31 -> 65 - 99 | G43: ='Final premium per member'!Y17 -> 43786 | H43: ='Final premium per member'!Z17 -> 49985 | I43: =$O$11 -> 0.1 | J43: =$O$12 -> 0.05 | K43: =$O$13 -> 0 | L43: =$O$14 -> 0.05 | M43: =$O$15 -> 0.005 | N43: =IF(G43="","",G43*(1-$O$16)) -> 34809.87 | O43: =IF(H43="","",H43*(1-$O$16)) -> 39738.075
...

Sheet Final premium per member
O1: Premium | Q1: Maternity Premium | R1: Total Premium | V1: Additional Maternity Premium | W1: A | X1: B | Y1: C | Z1: D | AA1: E
O2: =SUBTOTAL(9,O6:O506) -> 144218 | Q2: =SUBTOTAL(9,Q6:Q506) -> 20976 | R2: =SUBTOTAL(9,R6:R506) -> 165194 | W2: ='Approved Quote'!C36 -> 5244 | X2: {='Approved Quote'!C60:D60} -> 0 | Y2: 0
Q3: Total Census | R3: =SUBTOTAL(3,C6:C506) -> 17
W4: Category A | AA4: Category B | AE4: Category C | AI4: Category D | AM4: Category E | AQ4: Category F | AU4: Category G | AY4: Category H
A5: No. | B5: Name | C5: Date of birth | D5: Gender | E5: Category | F5: Relationship | G5: Marital Status | H5: Plan | I5: Salary | J5: Column Code | K5: Column No. | L5: Age (ALB) | M5: Age Bracket | N5: Age Bracket Code | O5: Premium | P5: Maternity Age Limit | Q5: Maternity Premium | R5: Premium | T5: Dubai Age Bracket | U5: AUH Age Bracket | V5: Age Bracket | W5: M (Principal) | X5: F (Principal) | Y5: M (Dependent) | Z5: F (Dependent) | AA5: M (Principal) | AB5: F (Principal) | AC5: M (Dependent) | AD5: F (Dependent) | AE5: M (Principal) | AF5: F (Principal) | AG5: M (Dependent) | AH5: F (Dependent) | AI5: M (Principal) | AJ5: F (Principal) | AK5: M (Dependent) | AL5: F (Dependent) | AM5: M (Principal) | AN5: F (Principal) | AO5: M (Dependent) | AP5: F (Dependent) | AQ5: M (Principal) | AR5: F (Principal) | AS5: M (Dependent) | AT5: F (Dependent) | AU5: M (Principal) | AV5: F (Principal) | AW5: M (Dependent) | AX5: F (Dependent) | AY5: M (Principal) | AZ5: F (Principal) | BA5: M (Dependent) | BB5: F (Dependent)
A6: 1 | B6: Vitty Yohannan Thomas | C6: 30593 | D6: MALE | E6: A | F6: Employee | G6: Married | H6: DXB | J6: =IF(D6="","",E6&LEFT(D6)&IF(F6="Employee","E","D")) -> AME | K6: =IF(J6="","",VLOOKUP(J6,$Y$19:$Z$50,2,FALSE)) -> 2 | L6: =IF(C6="","",DATEDIF(C6,'Premium Table'!$B$6,"Y")) -> 42 | M6: =IF(L6="","",IF(H6="","Choose Plan (DXB/AUH)",IF(H6="DXB",VLOOKUP(L6,$V$55:$W$154,2,FALSE),IF(H6="AUH",VLOOKUP(L6,$V$55:$X$154,3,FALSE),"Choose Plan (DXB/AUH)")))) -> 41 - 45 | N6: =IF(L6="","",IF(M6="","",IF(H6="DXB",VLOOKUP(M6,DXBAgeBr,3,FALSE),IF(H6="AUH",VLOOKUP(M6,AUHAgeBr,2,FALSE),"")))) -> 7 | O6: =IF(M6="","",VLOOKUP(N6,$V$5:$BB$17,K6,FALSE)) -> 8785 | P6: =IF(L6="","",IF(H6="DXB",46,IF(H6="AUH",51,""))) -> 46 | Q6: =IF(AND(LEFT(D6,1)="F",G6="Married",L6>17,L6<P6),HLOOKUP(E6,$W$1:$AA$2,2,FALSE),0) -> 0 | R6: =IF(M6="","",O6+Q6) -> 8785 | T6: 0 - 10 | U6: 0 - 17 | V6: 1 | W6: NA | X6: NA | Y6: ='Approved Quote'!G20 -> 6499 | Z6: ='Approved Quote'!I20 -> 5234 | AA6: NA | AB6: NA | AC6: ='Approved Quote'!G44 -> 0 | AD6: ='Approved Quote'!I44 -> 0 | AE6: NA | AF6: NA | AG6: ='Approved Quote'!G68 -> 0 | AH6: ='Approved Quote'!I68 -> 0 | AI6: NA | AJ6: NA | AK6: ='Approved Quote'!G92 -> 0 | AL6: ='Approved Quote'!I92 -> 0 | AM6: NA | AN6: NA | AQ6: NA | AR6: NA | AU6: NA | AV6: NA | AY6: NA | AZ6: NA
A7: =IF(C7="","",A6+1) -> 2 | B7: Alice Raju | C7: 30768 | D7: FEMALE | E7: A | F7: Spouse | G7: Married | H7: DXB | J7: =IF(D7="","",E7&LEFT(D7)&IF(F7="Employee","E","D")) -> AFD | K7: =IF(J7="","",VLOOKUP(J7,$Y$19:$Z$50,2,FALSE)) -> 5 | L7: =IF(C7="","",DATEDIF(C7,'Premium Table'!$B$6,"Y")) -> 41 | M7: =IF(L7="","",IF(H7="","Choose Plan (DXB/AUH)",IF(H7="DXB",VLOOKUP(L7,$V$55:$W$154,2,FALSE),IF(H7="AUH",VLOOKUP(L7,$V$55:$X$154,3,FALSE),"Choose Plan (DXB/AUH)")))) -> 41 - 45 | N7: =IF(L7="","",IF(M7="","",IF(H7="DXB",VLOOKUP(M7,DXBAgeBr,3,FALSE),IF(H7="AUH",VLOOKUP(M7,AUHAgeBr,2,FALSE),"")))) -> 7 | O7: =IF(M7="","",VLOOKUP(N7,$V$5:$BB$17,K7,FALSE)) -> 12068 | P7: =IF(L7="","",IF(H7="DXB",46,IF(H7="AUH",51,""))) -> 46 | Q7: =IF(AND(LEFT(D7,1)="F",G7="Married",L7>17,L7<P7),HLOOKUP(E7,$W$1:$AA$2,2,FALSE),0) -> 5244 | R7: =IF(M7="","",O7+Q7) -> 17312 | T7: 11 - 17 | U7: 18 - 40 | V7: 2 | W7: ='Approved Quote'!B21 -> 3157 | X7: ='Approved Quote'!D21 -> 3217 | Y7: ='Approved Quote'!G21 -> 4674 | Z7: ='Approved Quote'!I21 -> 4750 | AA7: ='Approved Quote'!B45 -> 0 | AB7: ='Approved Quote'!D45 -> 0 | AC7: ='Approved Quote'!G45 -> 0 | AD7: ='Approved Quote'!I45 -> 0 | AE7: ='Approved Quote'!B69 -> 0 | AF7: ='Approved Quote'!D69 -> 0 | AG7: ='Approved Quote'!G69 -> 0 | AH7: ='Approved Quote'!I69 -> 0 | AI7: ='Approved Quote'!B93 -> 0 | AJ7: ='Approved Quote'!D93 -> 0 | AK7: ='Approved Quote'!G93 -> 0 | AL7: ='Approved Quote'!I93 -> 0 | AQ7: NA | AR7: NA | AU7: NA | AV7: NA | AY7: NA | AZ7: NA
A8: =IF(C8="","",A7+1) -> 3 | B8: Beulah Vitty Thomas | C8: 41596 | D8: FEMALE | E8: A | F8: Child | G8: Single | H8: DXB | J8: =IF(D8="","",E8&LEFT(D8)&IF(F8="Employee","E","D")) -> AFD | K8: =IF(J8="","",VLOOKUP(J8,$Y$19:$Z$50,2,FALSE)) -> 5 | L8: =IF(C8="","",DATEDIF(C8,'Premium Table'!$B$6,"Y")) -> 12 | M8: =IF(L8="","",IF(H8="","Choose Plan (DXB/AUH)",IF(H8="DXB",VLOOKUP(L8,$V$55:$W$154,2,FALSE),IF(H8="AUH",VLOOKUP(L8,$V$55:$X$154,3,FALSE),"Choose Plan (DXB/AUH)")))) -> 11 - 17 | N8: =IF(L8="","",IF(M8="","",IF(H8="DXB",VLOOKUP(M8,DXBAgeBr,3,FALSE),IF(H8="AUH",VLOOKUP(M8,AUHAgeBr,2,FALSE),"")))) -> 2 | O8: =IF(M8="","",VLOOKUP(N8,$V$5:$BB$17,K8,FALSE)) -> 4750 | P8: =IF(L8="","",IF(H8="DXB",46,IF(H8="AUH",51,""))) -> 46 | Q8: =IF(AND(LEFT(D8,1)="F",G8="Married",L8>17,L8<P8),HLOOKUP(E8,$W$1:$AA$2,2,FALSE),0) -> 0 | R8: =IF(M8="","",O8+Q8) -> 4750 | T8: 18 - 25 | U8: 41 -59 | V8: 3 | W8: ='Approved Quote'!B22 -> 5253 | X8: ='Approved Quote'!D22 -> 5997 | Y8: ='Approved Quote'!G22 -> 5253 | Z8: ='Approved Quote'!I22 -> 5997 | AA8: ='Approved Quote'!B46 -> 0 | AB8: ='Approved Quote'!D46 -> 0 | AC8: ='Approved Quote'!G46 -> 0 | AD8: ='Approved Quote'!I46 -> 0 | AE8: ='Approved Quote'!B70 -> 0 | AF8: ='Approved Quote'!D70 -> 0 | AG8: ='Approved Quote'!G70 -> 0 | AH8: ='Approved Quote'!I70 -> 0 | AI8: ='Approved Quote'!B94 -> 0 | AJ8: ='Approved Quote'!D94 -> 0 | AK8: ='Approved Quote'!G94 -> 0 | AL8: ='Approved Quote'!I94 -> 0
A9: =IF(C9="","",A8+1) -> 4 | B9: Charlotte Vitty Thomas | C9: 43316 | D9: FEMALE | E9: A | F9: Child | G9: Single | H9: DXB | J9: =IF(D9="","",E9&LEFT(D9)&IF(F9="Employee","E","D")) -> AFD | K9: =IF(J9="","",VLOOKUP(J9,$Y$19:$Z$50,2,FALSE)) -> 5 | L9: =IF(C9="","",DATEDIF(C9,'Premium Table'!$B$6,"Y")) -> 7 | M9: =IF(L9="","",IF(H9="","Choose Plan (DXB/AUH)",IF(H9="DXB",VLOOKUP(L9,$V$55:$W$154,2,FALSE),IF(H9="AUH",VLOOKUP(L9,$V$55:$X$154,3,FALSE),"Choose Plan (DXB/AUH)")))) -> 0 - 10 | N9: =IF(L9="","",IF(M9="","",IF(H9="DXB",VLOOKUP(M9,DXBAgeBr,3,FALSE),IF(H9="AUH",VLOOKUP(M9,AUHAgeBr,2,FALSE),"")))) -> 1 | O9: =IF(M9="","",VLOOKUP(N9,$V$5:$BB$17,K9,FALSE)) -> 5234 | P9: =IF(L9="","",IF(H9="DXB",46,IF(H9="AUH",51,""))) -> 46 | Q9: =IF(AND(LEFT(D9,1)="F",G9="Married",L9>17,L9<P9),HLOOKUP(E9,$W$1:$AA$2,2,FALSE),0) -> 0 | R9: =IF(M9="","",O9+Q9) -> 5234 | T9: 26 - 30 | U9: 60 - 64 | V9: 4 | W9: ='Approved Quote'!B23 -> 5833 | X9: ='Approved Quote'!D23 -> 7304 | Y9: ='Approved Quote'!G23 -> 5833 | Z9: ='Approved Quote'!I23 -> 7304 | AA9: ='Approved Quote'!B47 -> 0 | AB9: ='Approved Quote'!D47 -> 0 | AC9: ='Approved Quote'!G47 -> 0 | AD9: ='Approved Quote'!I47 -> 0 | AE9: ='Approved Quote'!B71 -> 0 | AF9: ='Approved Quote'!D71 -> 0 | AG9: ='Approved Quote'!G71 -> 0 | AH9: ='Approved Quote'!I71 -> 0 | AI9: ='Approved Quote'!B95 -> 0 | AJ9: ='Approved Quote'!D95 -> 0 | AK9: ='Approved Quote'!G95 -> 0 | AL9: ='Approved Quote'!I95 -> 0
A10: =IF(C10="","",A9+1) -> 5 | B10: Evelyn Vitty Thomas | C10: 43958 | D10: FEMALE | E10: A | F10: Child | G10: Single | H10: DXB | J10: =IF(D10="","",E10&LEFT(D10)&IF(F10="Employee","E","D")) -> AFD | K10: =IF(J10="","",VLOOKUP(J10,$Y$19:$Z$50,2,FALSE)) -> 5 | L10: =IF(C10="","",DATEDIF(C10,'Premium Table'!$B$6,"Y")) -> 5 | M10: =IF(L10="","",IF(H10="","Choose Plan (DXB/AUH)",IF(H10="DXB",VLOOKUP(L10,$V$55:$W$154,2,FALSE),IF(H10="AUH",VLOOKUP(L10,$V$55:$X$154,3,FALSE),"Choose Plan (DXB/AUH)")))) -> 0 - 10 | N10: =IF(L10="","",IF(M10="","",IF(H10="DXB",VLOOKUP(M10,DXBAgeBr,3,FALSE),IF(H10="AUH",VLOOKUP(M10,AUHAgeBr,2,FALSE),"")))) -> 1 | O10: =IF(M10="","",VLOOKUP(N10,$V$5:$BB$17,K10,FALSE)) -> 5234 | P10: =IF(L10="","",IF(H10="DXB",46,IF(H10="AUH",51,""))) -> 46 | Q10: =IF(AND(LEFT(D10,1)="F",G10="Married",L10>17,L10<P10),HLOOKUP(E10,$W$1:$AA$2,2,FALSE),0) -> 0 | R10: =IF(M10="","",O10+Q10) -> 5234 | T10: 31 - 35 | U10: 65 - 99 | V10: 5 | W10: ='Approved Quote'!B24 -> 6915 | X10: ='Approved Quote'!D24 -> 8606 | Y10: ='Approved Quote'!G24 -> 6915 | Z10: ='Approved Quote'!I24 -> 8606 | AA10: ='Approved Quote'!B48 -> 0 | AB10: ='Approved Quote'!D48 -> 0 | AC10: ='Approved Quote'!G48 -> 0 | AD10: ='Approved Quote'!I48 -> 0 | AE10: ='Approved Quote'!B72 -> 0 | AF10: ='Approved Quote'!D72 -> 0 | AG10: ='Approved Quote'!G72 -> 0 | AH10: ='Approved Quote'!I72 -> 0 | AI10: ='Approved Quote'!B96 -> 0 | AJ10: ='Approved Quote'!D96 -> 0 | AK10: ='Approved Quote'!G96 -> 0 | AL10: ='Approved Quote'!I96 -> 0
A11: =IF(C11="","",A10+1) -> 6 | B11: Saniya Suri | C11: 35126 | D11: FEMALE | E11: A | F11: Employee | G11: Married | H11: DXB | J11: =IF(D11="","",E11&LEFT(D11)&IF(F11="Employee","E","D")) -> AFE | K11: =IF(J11="","",VLOOKUP(J11,$Y$19:$Z$50,2,FALSE)) -> 3 | L11: =IF(C11="","",DATEDIF(C11,'Premium Table'!$B$6,"Y")) -> 30 | M11: =IF(L11="","",IF(H11="","Choose Plan (DXB/AUH)",IF(H11="DXB",VLOOKUP(L11,$V$55:$W$154,2,FALSE),IF(H11="AUH",VLOOKUP(L11,$V$55:$X$154,3,FALSE),"Choose Plan (DXB/AUH)")))) -> 26 - 30 | N11: =IF(L11="","",IF(M11="","",IF(H11="DXB",VLOOKUP(M11,DXBAgeBr,3,FALSE),IF(H11="AUH",VLOOKUP(M11,AUHAgeBr,2,FALSE),"")))) -> 4 | O11: =IF(M11="","",VLOOKUP(N11,$V$5:$BB$17,K11,FALSE)) -> 7304 | P11: =IF(L11="","",IF(H11="DXB",46,IF(H11="AUH",51,""))) -> 46 | Q11: =IF(AND(LEFT(D11,1)="F",G11="Married",L11>17,L11<P11),HLOOKUP(E11,$W$1:$AA$2,2,FALSE),0) -> 5244 | R11: =IF(M11="","",O11+Q11) -> 12548 | T11: 36 - 40 | V11: 6 | W11: ='Approved Quote'!B25 -> 8397 | X11: ='Approved Quote'!D25 -> 10589 | Y11: ='Approved Quote'!G25 -> 8397 | Z11: ='Approved Quote'!I25 -> 10589 | AA11: ='Approved Quote'!B49 -> 0 | AB11: ='Approved Quote'!D49 -> 0 | AC11: ='Approved Quote'!G49 -> 0 | AD11: ='Approved Quote'!I49 -> 0 | AE11: ='Approved Quote'!B73 -> 0 | AF11: ='Approved Quote'!D73 -> 0 | AG11: ='Approved Quote'!G73 -> 0 | AH11: ='Approved Quote'!I73 -> 0 | AI11: ='Approved Quote'!B97 -> 0 | AJ11: ='Approved Quote'!D97 -> 0 | AK11: ='Approved Quote'!G97 -> 0 | AL11: ='Approved Quote'!I97 -> 0
A12: =IF(C12="","",A11+1) -> 7 | B12: Miraya Suri Hotwani | C12: 45839 | D12: FEMALE | E12: A | F12: Child | G12: Single | H12: DXB | J12: =IF(D12="","",E12&LEFT(D12)&IF(F12="Employee","E","D")) -> AFD | K12: =IF(J12="","",VLOOKUP(J12,$Y$19:$Z$50,2,FALSE)) -> 5 | L12: =IF(C12="","",DATEDIF(C12,'Premium Table'!$B$6,"Y")) -> 0 | M12: =IF(L12="","",IF(H12="","Choose Plan (DXB/AUH)",IF(H12="DXB",VLOOKUP(L12,$V$55:$W$154,2,FALSE),IF(H12="AUH",VLOOKUP(L12,$V$55:$X$154,3,FALSE),"Choose Plan (DXB/AUH)")))) -> 0 - 10 | N12: =IF(L12="","",IF(M12="","",IF(H12="DXB",VLOOKUP(M12,DXBAgeBr,3,FALSE),IF(H12="AUH",VLOOKUP(M12,AUHAgeBr,2,FALSE),"")))) -> 1 | O12: =IF(M12="","",VLOOKUP(N12,$V$5:$BB$17,K12,FALSE)) -> 5234 | P12: =IF(L12="","",IF(H12="DXB",46,IF(H12="AUH",51,""))) -> 46 | Q12: =IF(AND(LEFT(D12,1)="F",G12="Married",L12>17,L12<P12),HLOOKUP(E12,$W$1:$AA$2,2,FALSE),0) -> 0 | R12: =IF(M12="","",O12+Q12) -> 5234 | T12: 41 - 45 | V12: 7 | W12: ='Approved Quote'!B26 -> 8785 | X12: ='Approved Quote'!D26 -> 12068 | Y12: ='Approved Quote'!G26 -> 8795 | Z12: ='Approved Quote'!I26 -> 12068 | AA12: ='Approved Quote'!B50 -> 0 | AB12: ='Approved Quote'!D50 -> 0 | AC12: ='Approved Quote'!G50 -> 0 | AD12: ='Approved Quote'!I50 -> 0 | AE12: ='Approved Quote'!B74 -> 0 | AF12: ='Approved Quote'!D74 -> 0 | AG12: ='Approved Quote'!G74 -> 0 | AH12: ='Approved Quote'!I74 -> 0 | AI12: ='Approved Quote'!B98 -> 0 | AJ12: ='Approved Quote'!D98 -> 0 | AK12: ='Approved Quote'!G98 -> 0 | AL12: ='Approved Quote'!I98 -> 0
A13: =IF(C13="","",A12+1) -> 8 | B13: Shanaf Maliyakkal | C13: 32415 | D13: MALE | E13: A | F13: Employee | G13: Married | H13: DXB | J13: =IF(D13="","",E13&LEFT(D13)&IF(F13="Employee","E","D")) -> AME | K13: =IF(J13="","",VLOOKUP(J13,$Y$19:$Z$50,2,FALSE)) -> 2 | L13: =IF(C13="","",DATEDIF(C13,'Premium Table'!$B$6,"Y")) -> 37 | M13: =IF(L13="","",IF(H13="","Choose Plan (DXB/AUH)",IF(H13="DXB",VLOOKUP(L13,$V$55:$W$154,2,FALSE),IF(H13="AUH",VLOOKUP(L13,$V$55:$X$154,3,FALSE),"Choose Plan (DXB/AUH)")))) -> 36 - 40 | N13: =IF(L13="","",IF(M13="","",IF(H13="DXB",VLOOKUP(M13,DXBAgeBr,3,FALSE),IF(H13="AUH",VLOOKUP(M13,AUHAgeBr,2,FALSE),"")))) -> 6 | O13: =IF(M13="","",VLOOKUP(N13,$V$5:$BB$17,K13,FALSE)) -> 8397 | P13: =IF(L13="","",IF(H13="DXB",46,IF(H13="AUH",51,""))) -> 46 | Q13: =IF(AND(LEFT(D13,1)="F",G13="Married",L13>17,L13<P13),HLOOKUP(E13,$W$1:$AA$2,2,FALSE),0) -> 0 | R13: =IF(M13="","",O13+Q13) -> 8397 | T13: 46 - 50 | V13: 8 | W13: ='Approved Quote'!B27 -> 11304 | X13: ='Approved Quote'!D27 -> 14951 | Y13: ='Approved Quote'!G27 -> 11304 | Z13: ='Approved Quote'!I27 -> 14951 | AA13: ='Approved Quote'!B51 -> 0 | AB13: ='Approved Quote'!D51 -> 0 | AC13: ='Approved Quote'!G51 -> 0 | AD13: ='Approved Quote'!I51 -> 0 | AE13: ='Approved Quote'!B75 -> 0 | AF13: ='Approved Quote'!D75 -> 0 | AG13: ='Approved Quote'!G75 -> 0 | AH13: ='Approved Quote'!I75 -> 0 | AI13: ='Approved Quote'!B99 -> 0 | AJ13: ='Approved Quote'!D99 -> 0 | AK13: ='Approved Quote'!G99 -> 0 | AL13: ='Approved Quote'!I99 -> 0
A14: =IF(C14="","",A13+1) -> 9 | B14: Shafna Ponnachethiyil | C14: 35014 | D14: FEMALE | E14: A | F14: Spouse | G14: Married | H14: DXB | J14: =IF(D14="","",E14&LEFT(D14)&IF(F14="Employee","E","D")) -> AFD | K14: =IF(J14="","",VLOOKUP(J14,$Y$19:$Z$50,2,FALSE)) -> 5 | L14: =IF(C14="","",DATEDIF(C14,'Premium Table'!$B$6,"Y")) -> 30 | M14: =IF(L14="","",IF(H14="","Choose Plan (DXB/AUH)",IF(H14="DXB",VLOOKUP(L14,$V$55:$W$154,2,FALSE),IF(H14="AUH",VLOOKUP(L14,$V$55:$X$154,3,FALSE),"Choose Plan (DXB/AUH)")))) -> 26 - 30 | N14: =IF(L14="","",IF(M14="","",IF(H14="DXB",VLOOKUP(M14,DXBAgeBr,3,FALSE),IF(H14="AUH",VLOOKUP(M14,AUHAgeBr,2,FALSE),"")))) -> 4 | O14: =IF(M14="","",VLOOKUP(N14,$V$5:$BB$17,K14,FALSE)) -> 7304 | P14: =IF(L14="","",IF(H14="DXB",46,IF(H14="AUH",51,""))) -> 46 | Q14: =IF(AND(LEFT(D14,1)="F",G14="Married",L14>17,L14<P14),HLOOKUP(E14,$W$1:$AA$2,2,FALSE),0) -> 5244 | R14: =IF(M14="","",O14+Q14) -> 12548 | T14: 51 - 55 | V14: 9 | W14: ='Approved Quote'!B28 -> 14946 | X14: ='Approved Quote'!D28 -> 19507 | Y14: ='Approved Quote'!G28 -> 14946 | Z14: ='Approved Quote'!I28 -> 19507 | AA14: ='Approved Quote'!B52 -> 0 | AB14: ='Approved Quote'!D52 -> 0 | AC14: ='Approved Quote'!G52 -> 0 | AD14: ='Approved Quote'!I52 -> 0 | AE14: ='Approved Quote'!B76 -> 0 | AF14: ='Approved Quote'!D76 -> 0 | AG14: ='Approved Quote'!G76 -> 0 | AH14: ='Approved Quote'!I76 -> 0 | AI14: ='Approved Quote'!B100 -> 0 | AJ14: ='Approved Quote'!D100 -> 0 | AK14: ='Approved Quote'!G100 -> 0 | AL14: ='Approved Quote'!I100 -> 0
A15: =IF(C15="","",A14+1) -> 10 | B15: Haala Sehrish Maliyakkal | C15: 43617 | D15: FEMALE | E15: A | F15: Child | G15: Single | H15: DXB | J15: =IF(D15="","",E15&LEFT(D15)&IF(F15="Employee","E","D")) -> AFD | K15: =IF(J15="","",VLOOKUP(J15,$Y$19:$Z$50,2,FALSE)) -> 5 | L15: =IF(C15="","",DATEDIF(C15,'Premium Table'!$B$6,"Y")) -> 6 | M15: =IF(L15="","",IF(H15="","Choose Plan (DXB/AUH)",IF(H15="DXB",VLOOKUP(L15,$V$55:$W$154,2,FALSE),IF(H15="AUH",VLOOKUP(L15,$V$55:$X$154,3,FALSE),"Choose Plan (DXB/AUH)")))) -> 0 - 10 | N15: =IF(L15="","",IF(M15="","",IF(H15="DXB",VLOOKUP(M15,DXBAgeBr,3,FALSE),IF(H15="AUH",VLOOKUP(M15,AUHAgeBr,2,FALSE),"")))) -> 1 | O15: =IF(M15="","",VLOOKUP(N15,$V$5:$BB$17,K15,FALSE)) -> 5234 | P15: =IF(L15="","",IF(H15="DXB",46,IF(H15="AUH",51,""))) -> 46 | Q15: =IF(AND(LEFT(D15,1)="F",G15="Married",L15>17,L15<P15),HLOOKUP(E15,$W$1:$AA$2,2,FALSE),0) -> 0 | R15: =IF(M15="","",O15+Q15) -> 5234 | T15: 56 - 59 | V15: 10 | W15: ='Approved Quote'!B29 -> 20128 | X15: ='Approved Quote'!D29 -> 23729 | Y15: ='Approved Quote'!G29 -> 20128 | Z15: ='Approved Quote'!I29 -> 23729 | AA15: ='Approved Quote'!B53 -> 0 | AB15: ='Approved Quote'!D53 -> 0 | AC15: ='Approved Quote'!G53 -> 0 | AD15: ='Approved Quote'!I53 -> 0 | AE15: ='Approved Quote'!B77 -> 0 | AF15: ='Approved Quote'!D77 -> 0 | AG15: ='Approved Quote'!G77 -> 0 | AH15: ='Approved Quote'!I77 -> 0 | AI15: ='Approved Quote'!B101 -> 0 | AJ15: ='Approved Quote'!D101 -> 0 | AK15: ='Approved Quote'!G101 -> 0 | AL15: ='Approved Quote'!I101 -> 0
A16: =IF(C16="","",A15+1) -> 11 | B16: Zuhal Fatin Maliyakkal | C16: 45668 | D16: FEMALE | E16: A | F16: Child | G16: Single | H16: DXB | J16: =IF(D16="","",E16&LEFT(D16)&IF(F16="Employee","E","D")) -> AFD | K16: =IF(J16="","",VLOOKUP(J16,$Y$19:$Z$50,2,FALSE)) -> 5 | L16: =IF(C16="","",DATEDIF(C16,'Premium Table'!$B$6,"Y")) -> 1 | M16: =IF(L16="","",IF(H16="","Choose Plan (DXB/AUH)",IF(H16="DXB",VLOOKUP(L16,$V$55:$W$154,2,FALSE),IF(H16="AUH",VLOOKUP(L16,$V$55:$X$154,3,FALSE),"Choose Plan (DXB/AUH)")))) -> 0 - 10 | N16: =IF(L16="","",IF(M16="","",IF(H16="DXB",VLOOKUP(M16,DXBAgeBr,3,FALSE),IF(H16="AUH",VLOOKUP(M16,AUHAgeBr,2,FALSE),"")))) -> 1 | O16: =IF(M16="","",VLOOKUP(N16,$V$5:$BB$17,K16,FALSE)) -> 5234 | P16: =IF(L16="","",IF(H16="DXB",46,IF(H16="AUH",51,""))) -> 46 | Q16: =IF(AND(LEFT(D16,1)="F",G16="Married",L16>17,L16<P16),HLOOKUP(E16,$W$1:$AA$2,2,FALSE),0) -> 0 | R16: =IF(M16="","",O16+Q16) -> 5234 | T16: 60 - 64 | V16: 11 | W16: ='Approved Quote'!B30 -> 24628 | X16: ='Approved Quote'!D30 -> 28071 | Y16: ='Approved Quote'!G30 -> 24628 | Z16: ='Approved Quote'!I30 -> 28071 | AA16: ='Approved Quote'!B54 -> 0 | AB16: ='Approved Quote'!D54 -> 0 | AC16: ='Approved Quote'!G54 -> 0 | AD16: ='Approved Quote'!I54 -> 0 | AE16: ='Approved Quote'!B78 -> 0 | AF16: ='Approved Quote'!D78 -> 0 | AG16: ='Approved Quote'!G78 -> 0 | AH16: ='Approved Quote'!I78 -> 0 | AI16: ='Approved Quote'!B102 -> 0 | AJ16: ='Approved Quote'!D102 -> 0 | AK16: ='Approved Quote'!G102 -> 0 | AL16: ='Approved Quote'!I102 -> 0
A17: =IF(C17="","",A16+1) -> 12 | B17: Anshuman Patnaik | C17: 36726 | D17: MALE | E17: A | F17: Employee | G17: Single | H17: DXB | J17: =IF(D17="","",E17&LEFT(D17)&IF(F17="Employee","E","D")) -> AME | K17: =IF(J17="","",VLOOKUP(J17,$Y$19:$Z$50,2,FALSE)) -> 2 | L17: =IF(C17="","",DATEDIF(C17,'Premium Table'!$B$6,"Y")) -> 25 | M17: =IF(L17="","",IF(H17="","Choose Plan (DXB/AUH)",IF(H17="DXB",VLOOKUP(L17,$V$55:$W$154,2,FALSE),IF(H17="AUH",VLOOKUP(L17,$V$55:$X$154,3,FALSE),"Choose Plan (DXB/AUH)")))) -> 18 - 25 | N17: =IF(L17="","",IF(M17="","",IF(H17="DXB",VLOOKUP(M17,DXBAgeBr,3,FALSE),IF(H17="AUH",VLOOKUP(M17,AUHAgeBr,2,FALSE),"")))) -> 3 | O17: =IF(M17="","",VLOOKUP(N17,$V$5:$BB$17,K17,FALSE)) -> 5253 | P17: =IF(L17="","",IF(H17="DXB",46,IF(H17="AUH",51,""))) -> 46 | Q17: =IF(AND(LEFT(D17,1)="F",G17="Married",L17>17,L17<P17),HLOOKUP(E17,$W$1:$AA$2,2,FALSE),0) -> 0 | R17: =IF(M17="","",O17+Q17) -> 5253 | T17: 65 - 99 | V17: 12 | W17: ='Approved Quote'!B31 -> 43786 | X17: ='Approved Quote'!D31 -> 49985 | Y17: ='Approved Quote'!G31 -> 43786 | Z17: ='Approved Quote'!I31 -> 49985 | AA17: ='Approved Quote'!B55 -> 0 | AB17: ='Approved Quote'!D55 -> 0 | AC17: ='Approved Quote'!G55 -> 0 | AD17: ='Approved Quote'!I55 -> 0 | AE17: ='Approved Quote'!B79 -> 0 | AF17: ='Approved Quote'!D79 -> 0 | AG17: ='Approved Quote'!G79 -> 0 | AH17: ='Approved Quote'!I79 -> 0 | AI17: ='Approved Quote'!B103 -> 0 | AJ17: ='Approved Quote'!D103 -> 0 | AK17: ='Approved Quote'!G103 -> 0 | AL17: ='Approved Quote'!I103 -> 0
A18: =IF(C18="","",A17+1) -> 13 | B18: Anis Ahmed | C18: 24165 | D18: MALE | E18: A | F18: Employee | G18: Married | H18: DXB | J18: =IF(D18="","",E18&LEFT(D18)&IF(F18="Employee","E","D")) -> AME | K18: =IF(J18="","",VLOOKUP(J18,$Y$19:$Z$50,2,FALSE)) -> 2 | L18: =IF(C18="","",DATEDIF(C18,'Premium Table'!$B$6,"Y")) -> 60 | M18: =IF(L18="","",IF(H18="","Choose Plan (DXB/AUH)",IF(H18="DXB",VLOOKUP(L18,$V$55:$W$154,2,FALSE),IF(H18="AUH",VLOOKUP(L18,$V$55:$X$154,3,FALSE),"Choose Plan (DXB/AUH)")))) -> 60 - 64 | N18: =IF(L18="","",IF(M18="","",IF(H18="DXB",VLOOKUP(M18,DXBAgeBr,3,FALSE),IF(H18="AUH",VLOOKUP(M18,AUHAgeBr,2,FALSE),"")))) -> 11 | O18: =IF(M18="","",VLOOKUP(N18,$V$5:$BB$17,K18,FALSE)) -> 24628 | P18: =IF(L18="","",IF(H18="DXB",46,IF(H18="AUH",51,""))) -> 46 | Q18: =IF(AND(LEFT(D18,1)="F",G18="Married",L18>17,L18<P18),HLOOKUP(E18,$W$1:$AA$2,2,FALSE),0) -> 0 | R18: =IF(M18="","",O18+Q18) -> 24628
A19: =IF(C19="","",A18+1) -> 14 | B19: Suhana Lutfa Ahmed | C19: 26031 | D19: FEMALE | E19: A | F19: Spouse | G19: Married | H19: DXB | J19: =IF(D19="","",E19&LEFT(D19)&IF(F19="Employee","E","D")) -> AFD | K19: =IF(J19="","",VLOOKUP(J19,$Y$19:$Z$50,2,FALSE)) -> 5 | L19: =IF(C19="","",DATEDIF(C19,'Premium Table'!$B$6,"Y")) -> 54 | M19: =IF(L19="","",IF(H19="","Choose Plan (DXB/AUH)",IF(H19="DXB",VLOOKUP(L19,$V$55:$W$154,2,FALSE),IF(H19="AUH",VLOOKUP(L19,$V$55:$X$154,3,FALSE),"Choose Plan (DXB/AUH)")))) -> 51 - 55 | N19: =IF(L19="","",IF(M19="","",IF(H19="DXB",VLOOKUP(M19,DXBAgeBr,3,FALSE),IF(H19="AUH",VLOOKUP(M19,AUHAgeBr,2,FALSE),"")))) -> 9 | O19: =IF(M19="","",VLOOKUP(N19,$V$5:$BB$17,K19,FALSE)) -> 19507 | P19: =IF(L19="","",IF(H19="DXB",46,IF(H19="AUH",51,""))) -> 46 | Q19: =IF(AND(LEFT(D19,1)="F",G19="Married",L19>17,L19<P19),HLOOKUP(E19,$W$1:$AA$2,2,FALSE),0) -> 0 | R19: =IF(M19="","",O19+Q19) -> 19507 | V19: A | W19: M | X19: E | Y19: =V19&W19&X19 -> AME | Z19: 2
A20: =IF(C20="","",A19+1) -> 15 | B20: Arsalan Ahmed | C20: 34737 | D20: MALE | E20: A | F20: Employee | G20: Married | H20: DXB | J20: =IF(D20="","",E20&LEFT(D20)&IF(F20="Employee","E","D")) -> AME | K20: =IF(J20="","",VLOOKUP(J20,$Y$19:$Z$50,2,FALSE)) -> 2 | L20: =IF(C20="","",DATEDIF(C20,'Premium Table'!$B$6,"Y")) -> 31 | M20: =IF(L20="","",IF(H20="","Choose Plan (DXB/AUH)",IF(H20="DXB",VLOOKUP(L20,$V$55:$W$154,2,FALSE),IF(H20="AUH",VLOOKUP(L20,$V$55:$X$154,3,FALSE),"Choose Plan (DXB/AUH)")))) -> 31 - 35 | N20: =IF(L20="","",IF(M20="","",IF(H20="DXB",VLOOKUP(M20,DXBAgeBr,3,FALSE),IF(H20="AUH",VLOOKUP(M20,AUHAgeBr,2,FALSE),"")))) -> 5 | O20: =IF(M20="","",VLOOKUP(N20,$V$5:$BB$17,K20,FALSE)) -> 6915 | P20: =IF(L20="","",IF(H20="DXB",46,IF(H20="AUH",51,""))) -> 46 | Q20: =IF(AND(LEFT(D20,1)="F",G20="Married",L20>17,L20<P20),HLOOKUP(E20,$W$1:$AA$2,2,FALSE),0) -> 0 | R20: =IF(M20="","",O20+Q20) -> 6915 | V20: A | W20: F | X20: E | Y20: =V20&W20&X20 -> AFE | Z20: 3
A21: =IF(C21="","",A20+1) -> 16 | B21: Mannal Ajaz | C21: 35922 | D21: FEMALE | E21: A | F21: Spouse | G21: Married | H21: DXB | J21: =IF(D21="","",E21&LEFT(D21)&IF(F21="Employee","E","D")) -> AFD | K21: =IF(J21="","",VLOOKUP(J21,$Y$19:$Z$50,2,FALSE)) -> 5 | L21: =IF(C21="","",DATEDIF(C21,'Premium Table'!$B$6,"Y")) -> 27 | M21: =IF(L21="","",IF(H21="","Choose Plan (DXB/AUH)",IF(H21="DXB",VLOOKUP(L21,$V$55:$W$154,2,FALSE),IF(H21="AUH",VLOOKUP(L21,$V$55:$X$154,3,FALSE),"Choose Plan (DXB/AUH)")))) -> 26 - 30 | N21: =IF(L21="","",IF(M21="","",IF(H21="DXB",VLOOKUP(M21,DXBAgeBr,3,FALSE),IF(H21="AUH",VLOOKUP(M21,AUHAgeBr,2,FALSE),"")))) -> 4 | O21: =IF(M21="","",VLOOKUP(N21,$V$5:$BB$17,K21,FALSE)) -> 7304 | P21: =IF(L21="","",IF(H21="DXB",46,IF(H21="AUH",51,""))) -> 46 | Q21: =IF(AND(LEFT(D21,1)="F",G21="Married",L21>17,L21<P21),HLOOKUP(E21,$W$1:$AA$2,2,FALSE),0) -> 5244 | R21: =IF(M21="","",O21+Q21) -> 12548 | V21: A | W21: M | X21: D | Y21: =V21&W21&X21 -> AMD | Z21: 4
A22: =IF(C22="","",A21+1) -> 17 | B22: Shayan Ahmed | C22: 35231 | D22: MALE | E22: A | F22: Employee | G22: Single | H22: DXB | J22: =IF(D22="","",E22&LEFT(D22)&IF(F22="Employee","E","D")) -> AME | K22: =IF(J22="","",VLOOKUP(J22,$Y$19:$Z$50,2,FALSE)) -> 2 | L22: =IF(C22="","",DATEDIF(C22,'Premium Table'!$B$6,"Y")) -> 29 | M22: =IF(L22="","",IF(H22="","Choose Plan (DXB/AUH)",IF(H22="DXB",VLOOKUP(L22,$V$55:$W$154,2,FALSE),IF(H22="AUH",VLOOKUP(L22,$V$55:$X$154,3,FALSE),"Choose Plan (DXB/AUH)")))) -> 26 - 30 | N22: =IF(L22="","",IF(M22="","",IF(H22="DXB",VLOOKUP(M22,DXBAgeBr,3,FALSE),IF(H22="AUH",VLOOKUP(M22,AUHAgeBr,2,FALSE),"")))) -> 4 | O22: =IF(M22="","",VLOOKUP(N22,$V$5:$BB$17,K22,FALSE)) -> 5833 | P22: =IF(L22="","",IF(H22="DXB",46,IF(H22="AUH",51,""))) -> 46 | Q22: =IF(AND(LEFT(D22,1)="F",G22="Married",L22>17,L22<P22),HLOOKUP(E22,$W$1:$AA$2,2,FALSE),0) -> 0 | R22: =IF(M22="","",O22+Q22) -> 5833 | V22: A | W22: F | X22: D | Y22: =V22&W22&X22 -> AFD | Z22: 5
A23: =IF(C23="","",A22+1) | J23: =IF(D23="","",E23&LEFT(D23)&IF(F23="Employee","E","D")) | K23: =IF(J23="","",VLOOKUP(J23,$Y$19:$Z$50,2,FALSE)) | L23: =IF(C23="","",DATEDIF(C23,'Premium Table'!$B$6,"Y")) | M23: =IF(L23="","",IF(H23="","Choose Plan (DXB/AUH)",IF(H23="DXB",VLOOKUP(L23,$V$55:$W$154,2,FALSE),IF(H23="AUH",VLOOKUP(L23,$V$55:$X$154,3,FALSE),"Choose Plan (DXB/AUH)")))) | N23: =IF(L23="","",IF(M23="","",IF(H23="DXB",VLOOKUP(M23,DXBAgeBr,3,FALSE),IF(H23="AUH",VLOOKUP(M23,AUHAgeBr,2,FALSE),"")))) | O23: =IF(M23="","",VLOOKUP(N23,$V$5:$BB$17,K23,FALSE)) | P23: =IF(L23="","",IF(H23="DXB",46,IF(H23="AUH",51,""))) | Q23: =IF(AND(LEFT(D23,1)="F",G23="Married",L23>17,L23<P23),HLOOKUP(E23,$W$1:$AA$2,2,FALSE),0) -> 0 | R23: =IF(M23="","",O23+Q23) | V23: B | W23: M | X23: E | Y23: =V23&W23&X23 -> BME | Z23: 6
A24: =IF(C24="","",A23+1) | J24: =IF(D24="","",E24&LEFT(D24)&IF(F24="Employee","E","D")) | K24: =IF(J24="","",VLOOKUP(J24,$Y$19:$Z$50,2,FALSE)) | L24: =IF(C24="","",DATEDIF(C24,'Premium Table'!$B$6,"Y")) | M24: =IF(L24="","",IF(H24="","Choose Plan (DXB/AUH)",IF(H24="DXB",VLOOKUP(L24,$V$55:$W$154,2,FALSE),IF(H24="AUH",VLOOKUP(L24,$V$55:$X$154,3,FALSE),"Choose Plan (DXB/AUH)")))) | N24: =IF(L24="","",IF(M24="","",IF(H24="DXB",VLOOKUP(M24,DXBAgeBr,3,FALSE),IF(H24="AUH",VLOOKUP(M24,AUHAgeBr,2,FALSE),"")))) | O24: =IF(M24="","",VLOOKUP(N24,$V$5:$BB$17,K24,FALSE)) | P24: =IF(L24="","",IF(H24="DXB",46,IF(H24="AUH",51,""))) | Q24: =IF(AND(LEFT(D24,1)="F",G24="Married",L24>17,L24<P24),HLOOKUP(E24,$W$1:$AA$2,2,FALSE),0) -> 0 | R24: =IF(M24="","",O24+Q24) | V24: B | W24: F | X24: E | Y24: =V24&W24&X24 -> BFE | Z24: 7
A25: =IF(C25="","",A24+1) | J25: =IF(D25="","",E25&LEFT(D25)&IF(F25="Employee","E","D")) | K25: =IF(J25="","",VLOOKUP(J25,$Y$19:$Z$50,2,FALSE)) | L25: =IF(C25="","",DATEDIF(C25,'Premium Table'!$B$6,"Y")) | M25: =IF(L25="","",IF(H25="","Choose Plan (DXB/AUH)",IF(H25="DXB",VLOOKUP(L25,$V$55:$W$154,2,FALSE),IF(H25="AUH",VLOOKUP(L25,$V$55:$X$154,3,FALSE),"Choose Plan (DXB/AUH)")))) | N25: =IF(L25="","",IF(M25="","",IF(H25="DXB",VLOOKUP(M25,DXBAgeBr,3,FALSE),IF(H25="AUH",VLOOKUP(M25,AUHAgeBr,2,FALSE),"")))) | O25: =IF(M25="","",VLOOKUP(N25,$V$5:$BB$17,K25,FALSE)) | P25: =IF(L25="","",IF(H25="DXB",46,IF(H25="AUH",51,""))) | Q25: =IF(AND(LEFT(D25,1)="F",G25="Married",L25>17,L25<P25),HLOOKUP(E25,$W$1:$AA$2,2,FALSE),0) -> 0 | R25: =IF(M25="","",O25+Q25) | V25: B | W25: M | X25: D | Y25: =V25&W25&X25 -> BMD | Z25: 8
A26: =IF(C26="","",A25+1) | J26: =IF(D26="","",E26&LEFT(D26)&IF(F26="Employee","E","D")) | K26: =IF(J26="","",VLOOKUP(J26,$Y$19:$Z$50,2,FALSE)) | L26: =IF(C26="","",DATEDIF(C26,'Premium Table'!$B$6,"Y")) | M26: =IF(L26="","",IF(H26="","Choose Plan (DXB/AUH)",IF(H26="DXB",VLOOKUP(L26,$V$55:$W$154,2,FALSE),IF(H26="AUH",VLOOKUP(L26,$V$55:$X$154,3,FALSE),"Choose Plan (DXB/AUH)")))) | N26: =IF(L26="","",IF(M26="","",IF(H26="DXB",VLOOKUP(M26,DXBAgeBr,3,FALSE),IF(H26="AUH",VLOOKUP(M26,AUHAgeBr,2,FALSE),"")))) | O26: =IF(M26="","",VLOOKUP(N26,$V$5:$BB$17,K26,FALSE)) | P26: =IF(L26="","",IF(H26="DXB",46,IF(H26="AUH",51,""))) | Q26: =IF(AND(LEFT(D26,1)="F",G26="Married",L26>17,L26<P26),HLOOKUP(E26,$W$1:$AA$2,2,FALSE),0) -> 0 | R26: =IF(M26="","",O26+Q26) | V26: B | W26: F | X26: D | Y26: =V26&W26&X26 -> BFD | Z26: 9
A27: =IF(C27="","",A26+1) | J27: =IF(D27="","",E27&LEFT(D27)&IF(F27="Employee","E","D")) | K27: =IF(J27="","",VLOOKUP(J27,$Y$19:$Z$50,2,FALSE)) | L27: =IF(C27="","",DATEDIF(C27,'Premium Table'!$B$6,"Y")) | M27: =IF(L27="","",IF(H27="","Choose Plan (DXB/AUH)",IF(H27="DXB",VLOOKUP(L27,$V$55:$W$154,2,FALSE),IF(H27="AUH",VLOOKUP(L27,$V$55:$X$154,3,FALSE),"Choose Plan (DXB/AUH)")))) | N27: =IF(L27="","",IF(M27="","",IF(H27="DXB",VLOOKUP(M27,DXBAgeBr,3,FALSE),IF(H27="AUH",VLOOKUP(M27,AUHAgeBr,2,FALSE),"")))) | O27: =IF(M27="","",VLOOKUP(N27,$V$5:$BB$17,K27,FALSE)) | P27: =IF(L27="","",IF(H27="DXB",46,IF(H27="AUH",51,""))) | Q27: =IF(AND(LEFT(D27,1)="F",G27="Married",L27>17,L27<P27),HLOOKUP(E27,$W$1:$AA$2,2,FALSE),0) -> 0 | R27: =IF(M27="","",O27+Q27) | V27: C | W27: M | X27: E | Y27: =V27&W27&X27 -> CME | Z27: 10
A28: =IF(C28="","",A27+1) | J28: =IF(D28="","",E28&LEFT(D28)&IF(F28="Employee","E","D")) | K28: =IF(J28="","",VLOOKUP(J28,$Y$19:$Z$50,2,FALSE)) | L28: =IF(C28="","",DATEDIF(C28,'Premium Table'!$B$6,"Y")) | M28: =IF(L28="","",IF(H28="","Choose Plan (DXB/AUH)",IF(H28="DXB",VLOOKUP(L28,$V$55:$W$154,2,FALSE),IF(H28="AUH",VLOOKUP(L28,$V$55:$X$154,3,FALSE),"Choose Plan (DXB/AUH)")))) | N28: =IF(L28="","",IF(M28="","",IF(H28="DXB",VLOOKUP(M28,DXBAgeBr,3,FALSE),IF(H28="AUH",VLOOKUP(M28,AUHAgeBr,2,FALSE),"")))) | O28: =IF(M28="","",VLOOKUP(N28,$V$5:$BB$17,K28,FALSE)) | P28: =IF(L28="","",IF(H28="DXB",46,IF(H28="AUH",51,""))) | Q28: =IF(AND(LEFT(D28,1)="F",G28="Married",L28>17,L28<P28),HLOOKUP(E28,$W$1:$AA$2,2,FALSE),0) -> 0 | R28: =IF(M28="","",O28+Q28) | V28: C | W28: F | X28: E | Y28: =V28&W28&X28 -> CFE | Z28: 11
A29: =IF(C29="","",A28+1) | J29: =IF(D29="","",E29&LEFT(D29)&IF(F29="Employee","E","D")) | K29: =IF(J29="","",VLOOKUP(J29,$Y$19:$Z$50,2,FALSE)) | L29: =IF(C29="","",DATEDIF(C29,'Premium Table'!$B$6,"Y")) | M29: =IF(L29="","",IF(H29="","Choose Plan (DXB/AUH)",IF(H29="DXB",VLOOKUP(L29,$V$55:$W$154,2,FALSE),IF(H29="AUH",VLOOKUP(L29,$V$55:$X$154,3,FALSE),"Choose Plan (DXB/AUH)")))) | N29: =IF(L29="","",IF(M29="","",IF(H29="DXB",VLOOKUP(M29,DXBAgeBr,3,FALSE),IF(H29="AUH",VLOOKUP(M29,AUHAgeBr,2,FALSE),"")))) | O29: =IF(M29="","",VLOOKUP(N29,$V$5:$BB$17,K29,FALSE)) | P29: =IF(L29="","",IF(H29="DXB",46,IF(H29="AUH",51,""))) | Q29: =IF(AND(LEFT(D29,1)="F",G29="Married",L29>17,L29<P29),HLOOKUP(E29,$W$1:$AA$2,2,FALSE),0) -> 0 | R29: =IF(M29="","",O29+Q29) | V29: C | W29: M | X29: D | Y29: =V29&W29&X29 -> CMD | Z29: 12
A30: =IF(C30="","",A29+1) | J30: =IF(D30="","",E30&LEFT(D30)&IF(F30="Employee","E","D")) | K30: =IF(J30="","",VLOOKUP(J30,$Y$19:$Z$50,2,FALSE)) | L30: =IF(C30="","",DATEDIF(C30,'Premium Table'!$B$6,"Y")) | M30: =IF(L30="","",IF(H30="","Choose Plan (DXB/AUH)",IF(H30="DXB",VLOOKUP(L30,$V$55:$W$154,2,FALSE),IF(H30="AUH",VLOOKUP(L30,$V$55:$X$154,3,FALSE),"Choose Plan (DXB/AUH)")))) | N30: =IF(L30="","",IF(M30="","",IF(H30="DXB",VLOOKUP(M30,DXBAgeBr,3,FALSE),IF(H30="AUH",VLOOKUP(M30,AUHAgeBr,2,FALSE),"")))) | O30: =IF(M30="","",VLOOKUP(N30,$V$5:$BB$17,K30,FALSE)) | P30: =IF(L30="","",IF(H30="DXB",46,IF(H30="AUH",51,""))) | Q30: =IF(AND(LEFT(D30,1)="F",G30="Married",L30>17,L30<P30),HLOOKUP(E30,$W$1:$AA$2,2,FALSE),0) -> 0 | R30: =IF(M30="","",O30+Q30) | V30: C | W30: F | X30: D | Y30: =V30&W30&X30 -> CFD | Z30: 13
A31: =IF(C31="","",A30+1) | J31: =IF(D31="","",E31&LEFT(D31)&IF(F31="Employee","E","D")) | K31: =IF(J31="","",VLOOKUP(J31,$Y$19:$Z$50,2,FALSE)) | L31: =IF(C31="","",DATEDIF(C31,'Premium Table'!$B$6,"Y")) | M31: =IF(L31="","",IF(H31="","Choose Plan (DXB/AUH)",IF(H31="DXB",VLOOKUP(L31,$V$55:$W$154,2,FALSE),IF(H31="AUH",VLOOKUP(L31,$V$55:$X$154,3,FALSE),"Choose Plan (DXB/AUH)")))) | N31: =IF(L31="","",IF(M31="","",IF(H31="DXB",VLOOKUP(M31,DXBAgeBr,3,FALSE),IF(H31="AUH",VLOOKUP(M31,AUHAgeBr,2,FALSE),"")))) | O31: =IF(M31="","",VLOOKUP(N31,$V$5:$BB$17,K31,FALSE)) | P31: =IF(L31="","",IF(H31="DXB",46,IF(H31="AUH",51,""))) | Q31: =IF(AND(LEFT(D31,1)="F",G31="Married",L31>17,L31<P31),HLOOKUP(E31,$W$1:$AA$2,2,FALSE),0) -> 0 | R31: =IF(M31="","",O31+Q31) | V31: D | W31: M | X31: E | Y31: =V31&W31&X31 -> DME | Z31: 14
A32: =IF(C32="","",A31+1) | J32: =IF(D32="","",E32&LEFT(D32)&IF(F32="Employee","E","D")) | K32: =IF(J32="","",VLOOKUP(J32,$Y$19:$Z$50,2,FALSE)) | L32: =IF(C32="","",DATEDIF(C32,'Premium Table'!$B$6,"Y")) | M32: =IF(L32="","",IF(H32="","Choose Plan (DXB/AUH)",IF(H32="DXB",VLOOKUP(L32,$V$55:$W$154,2,FALSE),IF(H32="AUH",VLOOKUP(L32,$V$55:$X$154,3,FALSE),"Choose Plan (DXB/AUH)")))) | N32: =IF(L32="","",IF(M32="","",IF(H32="DXB",VLOOKUP(M32,DXBAgeBr,3,FALSE),IF(H32="AUH",VLOOKUP(M32,AUHAgeBr,2,FALSE),"")))) | O32: =IF(M32="","",VLOOKUP(N32,$V$5:$BB$17,K32,FALSE)) | P32: =IF(L32="","",IF(H32="DXB",46,IF(H32="AUH",51,""))) | Q32: =IF(AND(LEFT(D32,1)="F",G32="Married",L32>17,L32<P32),HLOOKUP(E32,$W$1:$AA$2,2,FALSE),0) -> 0 | R32: =IF(M32="","",O32+Q32) | V32: D | W32: F | X32: E | Y32: =V32&W32&X32 -> DFE | Z32: 15
A33: =IF(C33="","",A32+1) | J33: =IF(D33="","",E33&LEFT(D33)&IF(F33="Employee","E","D")) | K33: =IF(J33="","",VLOOKUP(J33,$Y$19:$Z$50,2,FALSE)) | L33: =IF(C33="","",DATEDIF(C33,'Premium Table'!$B$6,"Y")) | M33: =IF(L33="","",IF(H33="","Choose Plan (DXB/AUH)",IF(H33="DXB",VLOOKUP(L33,$V$55:$W$154,2,FALSE),IF(H33="AUH",VLOOKUP(L33,$V$55:$X$154,3,FALSE),"Choose Plan (DXB/AUH)")))) | N33: =IF(L33="","",IF(M33="","",IF(H33="DXB",VLOOKUP(M33,DXBAgeBr,3,FALSE),IF(H33="AUH",VLOOKUP(M33,AUHAgeBr,2,FALSE),"")))) | O33: =IF(M33="","",VLOOKUP(N33,$V$5:$BB$17,K33,FALSE)) | P33: =IF(L33="","",IF(H33="DXB",46,IF(H33="AUH",51,""))) | Q33: =IF(AND(LEFT(D33,1)="F",G33="Married",L33>17,L33<P33),HLOOKUP(E33,$W$1:$AA$2,2,FALSE),0) -> 0 | R33: =IF(M33="","",O33+Q33) | V33: D | W33: M | X33: D | Y33: =V33&W33&X33 -> DMD | Z33: 16
A34: =IF(C34="","",A33+1) | J34: =IF(D34="","",E34&LEFT(D34)&IF(F34="Employee","E","D")) | K34: =IF(J34="","",VLOOKUP(J34,$Y$19:$Z$50,2,FALSE)) | L34: =IF(C34="","",DATEDIF(C34,'Premium Table'!$B$6,"Y")) | M34: =IF(L34="","",IF(H34="","Choose Plan (DXB/AUH)",IF(H34="DXB",VLOOKUP(L34,$V$55:$W$154,2,FALSE),IF(H34="AUH",VLOOKUP(L34,$V$55:$X$154,3,FALSE),"Choose Plan (DXB/AUH)")))) | N34: =IF(L34="","",IF(M34="","",IF(H34="DXB",VLOOKUP(M34,DXBAgeBr,3,FALSE),IF(H34="AUH",VLOOKUP(M34,AUHAgeBr,2,FALSE),"")))) | O34: =IF(M34="","",VLOOKUP(N34,$V$5:$BB$17,K34,FALSE)) | P34: =IF(L34="","",IF(H34="DXB",46,IF(H34="AUH",51,""))) | Q34: =IF(AND(LEFT(D34,1)="F",G34="Married",L34>17,L34<P34),HLOOKUP(E34,$W$1:$AA$2,2,FALSE),0) -> 0 | R34: =IF(M34="","",O34+Q34) | V34: D | W34: F | X34: D | Y34: =V34&W34&X34 -> DFD | Z34: 17
... A50: =IF(C50="","",A49+1) | J50: =IF(D50="","",E50&LEFT(D50)&IF(F50="Employee","E","D")) | K50: =IF(J50="","",VLOOKUP(J50,$Y$19:$Z$50,2,FALSE)) | L50: =IF(C50="","",DATEDIF(C50,'Premium Table'!$B$6,"Y")) | M50: =IF(L50="","",IF(H50="","Choose Plan (DXB/AUH)",IF(H50="DXB",VLOOKUP(L50,$V$55:$W$154,2,FALSE),IF(H50="AUH",VLOOKUP(L50,$V$55:$X$154,3,FALSE),"Choose Plan (DXB/AUH)")))) | N50: =IF(L50="","",IF(M50="","",IF(H50="DXB",VLOOKUP(M50,DXBAgeBr,3,FALSE),IF(H50="AUH",VLOOKUP(M50,AUHAgeBr,2,FALSE),"")))) | O50: =IF(M50="","",VLOOKUP(N50,$V$5:$BB$17,K50,FALSE)) | P50: =IF(L50="","",IF(H50="DXB",46,IF(H50="AUH",51,""))) | Q50: =IF(AND(LEFT(D50,1)="F",G50="Married",L50>17,L50<P50),HLOOKUP(E50,$W$1:$AA$2,2,FALSE),0) -> 0 | R50: =IF(M50="","",O50+Q50) | V50: H | W50: F | X50: D | Y50: =V50&W50&X50 -> HFD | Z50: 33
A51: =IF(C51="","",A50+1) | J51: =IF(D51="","",E51&LEFT(D51)&IF(F51="Employee","E","D")) | K51: =IF(J51="","",VLOOKUP(J51,$Y$19:$Z$50,2,FALSE)) | L51: =IF(C51="","",DATEDIF(C51,'Premium Table'!$B$6,"Y")) | M51: =IF(L51="","",IF(H51="","Choose Plan (DXB/AUH)",IF(H51="DXB",VLOOKUP(L51,$V$55:$W$154,2,FALSE),IF(H51="AUH",VLOOKUP(L51,$V$55:$X$154,3,FALSE),"Choose Plan (DXB/AUH)")))) | N51: =IF(L51="","",IF(M51="","",IF(H51="DXB",VLOOKUP(M51,DXBAgeBr,3,FALSE),IF(H51="AUH",VLOOKUP(M51,AUHAgeBr,2,FALSE),"")))) | O51: =IF(M51="","",VLOOKUP(N51,$V$5:$BB$17,K51,FALSE)) | P51: =IF(L51="","",IF(H51="DXB",46,IF(H51="AUH",51,""))) | Q51: =IF(AND(LEFT(D51,1)="F",G51="Married",L51>17,L51<P51),HLOOKUP(E51,$W$1:$AA$2,2,FALSE),0) -> 0 | R51: =IF(M51="","",O51+Q51)
A52: =IF(C52="","",A51+1) | J52: =IF(D52="","",E52&LEFT(D52)&IF(F52="Employee","E","D")) | K52: =IF(J52="","",VLOOKUP(J52,$Y$19:$Z$50,2,FALSE)) | L52: =IF(C52="","",DATEDIF(C52,'Premium Table'!$B$6,"Y")) | M52: =IF(L52="","",IF(H52="","Choose Plan (DXB/AUH)",IF(H52="DXB",VLOOKUP(L52,$V$55:$W$154,2,FALSE),IF(H52="AUH",VLOOKUP(L52,$V$55:$X$154,3,FALSE),"Choose Plan (DXB/AUH)")))) | N52: =IF(L52="","",IF(M52="","",IF(H52="DXB",VLOOKUP(M52,DXBAgeBr,3,FALSE),IF(H52="AUH",VLOOKUP(M52,AUHAgeBr,2,FALSE),"")))) | O52: =IF(M52="","",VLOOKUP(N52,$V$5:$BB$17,K52,FALSE)) | P52: =IF(L52="","",IF(H52="DXB",46,IF(H52="AUH",51,""))) | Q52: =IF(AND(LEFT(D52,1)="F",G52="Married",L52>17,L52<P52),HLOOKUP(E52,$W$1:$AA$2,2,FALSE),0) -> 0 | R52: =IF(M52="","",O52+Q52)
A53: =IF(C53="","",A52+1) | J53: =IF(D53="","",E53&LEFT(D53)&IF(F53="Employee","E","D")) | K53: =IF(J53="","",VLOOKUP(J53,$Y$19:$Z$50,2,FALSE)) | L53: =IF(C53="","",DATEDIF(C53,'Premium Table'!$B$6,"Y")) | M53: =IF(L53="","",IF(H53="","Choose Plan (DXB/AUH)",IF(H53="DXB",VLOOKUP(L53,$V$55:$W$154,2,FALSE),IF(H53="AUH",VLOOKUP(L53,$V$55:$X$154,3,FALSE),"Choose Plan (DXB/AUH)")))) | N53: =IF(L53="","",IF(M53="","",IF(H53="DXB",VLOOKUP(M53,DXBAgeBr,3,FALSE),IF(H53="AUH",VLOOKUP(M53,AUHAgeBr,2,FALSE),"")))) | O53: =IF(M53="","",VLOOKUP(N53,$V$5:$BB$17,K53,FALSE)) | P53: =IF(L53="","",IF(H53="DXB",46,IF(H53="AUH",51,""))) | Q53: =IF(AND(LEFT(D53,1)="F",G53="Married",L53>17,L53<P53),HLOOKUP(E53,$W$1:$AA$2,2,FALSE),0) -> 0 | R53: =IF(M53="","",O53+Q53)
